Workbook

Sheet Menu
B1: GUIA DE PREENCHIMENTO E PADRONIZAÇÃO
B4: Base de Midia 2026 | Digital e Offline

Sheet Dicionário de Dados Digital
A1: Dicionário Digital | B1: Voltar Menu
A3: Nome da Coluna | B3: Tipo do Dado | C3: Descrição | D3: RROI | E3: Regras de Preenchimento | F3: Lista
A4: bd_campaign_id_api | B4: string | C4: ID numérico (código) da campanha conforme retornado pela API da plataforma. | E4: Sem exceções
A5: bd_date | B5: string | C5: Data de veiculação da mídia referente (granularidade diária). | D5: SIM | E5: Sem exceções
A6: bd_device_platform | B6: string | C6: Tipo de dispositivo onde a impressão foi entregue (ex.: mobile_app, mobile_web, desktop, tablet, connected tv, tiktok, smart phone, set top box). | E6: Sem exceções
A7: bd_extraction_source | B7: string | C7: Origem/método da extração dos dados (ex.: api, compra direta). | E7: Sem exceções | F7: =IFERROR( HYPERLINK( "#'Valores Permitidos Digital'!" & SUBSTITUTE( ADDRESS(1,MATCH(A7,'Valores Permitidos Digital'!$5:$5,0),4), "1", "3" ), "Valores Permitidos" ), "-" ) -> Valores Permitidos
A8: bd_placement_platform | B8: string | C8: Placement específico onde o anúncio foi exibido (ex.: feed, marketplace, instagram_reels, facebook_reels, instagram_stories, search, instream_video, etc.). | E8: Sem exceções
A9: bd_platform | B9: string | C9: Plataforma de mídia onde a campanha foi veiculada (ex.: meta, dv360 youtube, tiktok, google ads, pinterest, mercadolivre, hypr, flashtalking). | D9: SIM | E9: Sem exceções | F9: Valores Permitidos
A10: bd_platform_account_name | B10: string | C10: Nome da conta na plataforma de mídia (ex.: br_omo_non-collab_na_ul-hc-omosabao). | E10: Sem exceções
A11: bd_platform_accountname_api | B11: string | C11: Nome da conta na plataforma conforme retornado pela API (espelho técnico de bd_platform_account_name). | E11: Sem exceções
A12: bd_platform_type | B12: string | C12: Tipo/categoria da plataforma agregada (ex.: social, search, portal, programática). | E12: Sem exceções
A13: ft_ad_objective | B13: string | C13: Objetivo do anúncio conforme configurado na veiculação (ex.: reach, views, click, na, awa, cons, conv). | E13: Sem exceções
A14: ft_adgroup_extra | B14: string | C14: Campo de preenchimento livre para classificações especiais de grupos de anúncio caso necessário. | E14: Campo livre
A15: ft_audience_shortname | B15: string | C15: Nome curto/abreviado da audiência segmentada (ex.: intaff-beawels-beatmave, int-shofsh-cosmetics). Campo livre a partir de 2026. | E15: Campo livre
A16: ft_brand_lift | B16: string | C16: Indicador de mensuração de Brand Lift (ex.: brdlft-y=com estudo, brdlft-n=sem estudo). | E16: Sem exceções | F16: =IFERROR( HYPERLINK( "#'Valores Permitidos Digital'!" & SUBSTITUTE( ADDRESS(1,MATCH(A16,'Valores Permitidos Digital'!$5:$5,0),4), "1", "5" ), "Valores Permitidos" ), "-" ) -> Valores Permitidos
A17: ft_campaign_local | B17: string | C17: Nome da campanha conforme retornado pela API da plataforma. | D17: SIM | E17: Sem exceções
A18: ft_campaignlocal_extra | B18: string | C18: Campo de preenchimento livre para classificações especiais de campanhas, caso necessário. | D18: SIM | E18: Campo livre
A19: ft_creativename_extra | B19: string | C19: Campo de preenchimento livre para classificações especiais de nomes de criativos, caso necessário. | E19: Campo livre
A20: ft_directdeal_type | B20: string | C20: Identificação do caráter de execução da linha. Apenas mídia deve ser reportada. | E20: Sem exceções | F20: =IFERROR( HYPERLINK( "#'Valores Permitidos Digital'!" & SUBSTITUTE( ADDRESS(1,MATCH(A20,'Valores Permitidos Digital'!$5:$5,0),4), "1", "5" ), "Valores Permitidos" ), "-" ) -> Valores Permitidos
A21: ft_format_type_local | B21: string | C21: Tipo de formato tratado/local (ex.: vid, image, carousel, infeed, texto...). | E21: Sem exceções | F21: =IFERROR( HYPERLINK( "#'Valores Permitidos Digital'!" & SUBSTITUTE( ADDRESS(1,MATCH(A21,'Valores Permitidos Digital'!$5:$5,0),4), "1", "5" ), "Valores Permitidos" ), "-" ) -> Valores Permitidos
A22: ft_formataggregated | B22: string | C22: Formato agregado/normalizado para análise (ex.: video, display, texto). | D22: SIM | E22: Sem exceções | F22: =IFERROR( HYPERLINK( "#'Valores Permitidos Digital'!" & SUBSTITUTE( ADDRESS(1,MATCH(A22,'Valores Permitidos Digital'!$5:$5,0),4), "1", "5" ), "Valores Permitidos" ), "-" ) -> Valores Permitidos
A23: ft_formatgroup | B23: string | C23: Essa coluna será descontinuada em setembro. Por padrão, repetir valores de 'ft_formataggregated'. | E23: Sem exceções
A24: ft_influencer_brand | B24: string | C24: Identificação do viés criativo, diferenciando entre comunicação de marca (brand) ou influenciador (influencer). | D24: SIM | E24: Sem exceções | F24: =IFERROR( HYPERLINK( "#'Valores Permitidos Digital'!" & SUBSTITUTE( ADDRESS(1,MATCH(A24,'Valores Permitidos Digital'!$5:$5,0),4), "1", "5" ), "Valores Permitidos" ), "-" ) -> Valores Permitidos
A25: ft_influencer_name | B25: string | C25: Nome do influenciador utilizado na peça. | E25: Sem exceções
A26: ft_influencer_profile | B26: string | C26: Nome de usuário (Tag, handle) do influenciador. Não deve ter '@' nem underlines. | E26: Sem exceções
A27: ft_insertionorder_extra | B27: string | C27: Campo de preenchimento livre para identificações adicionais de ordem de insersão, caso necessário. | E27: Campo livre
A28: ft_lineitem_extra | B28: string | C28: Campo de preenchimento livre para identificações adicionais de line item, caso necessário. | E28: Sem exceções
A29: ft_region | B29: string | C29: Descrição/valor da localização segmentada (ex.: nac, sul, ne-se, se, se-sul, no-se). | E29: Sem exceções | F29: =IFERROR( HYPERLINK( "#'Valores Permitidos Digital'!" & SUBSTITUTE( ADDRESS(1,MATCH(A29,'Valores Permitidos Digital'!$5:$5,0),4), "1", "5" ), "Valores Permitidos" ), "-" ) -> Valores Permitidos
A30: ft_location_type | B30: string | C30: Tipo de segmentação de localização (ex.: regiao). | E30: Sem exceções | F30: =IFERROR( HYPERLINK( "#'Valores Permitidos Digital'!" & SUBSTITUTE( ADDRESS(1,MATCH(A30,'Valores Permitidos Digital'!$5:$5,0),4), "1", "5" ), "Valores Permitidos" ), "-" ) -> Valores Permitidos
A31: ft_placement_type_local | B31: string | C31: Tipo de placement tratado/local (ex.: multi, fed-stor, fed-stor-reel, reel, feednskp, vvcskip, instm-nskipyt, etc.). | E31: Sem exceções | F31: =IFERROR( HYPERLINK( "#'Valores Permitidos Digital'!" & SUBSTITUTE( ADDRESS(1,MATCH(A31,'Valores Permitidos Digital'!$5:$5,0),4), "1", "5" ), "Valores Permitidos" ), "-" ) -> Valores Permitidos
A32: ft_podcast_qtycontracted | B32: bigint | C32: Quantidade de entregas contratadas em campanhas de podcast (geralmente 0 fora de podcast). | E32: Valores nulos aceitos (0, blank)
A33: ft_publisher | B33: string | C33: Publisher/veículo onde a peça foi veiculada (ex.: facebook, instagram, youtube, tiktok, pinterest, mercado livre, gshow, hypr, folha, magnite, dv360-programmatic, kwai). | D33: SIM | E33: Sem exceções | F33: =IFERROR( HYPERLINK( "#'Valores Permitidos Digital'!" & SUBSTITUTE( ADDRESS(1,MATCH(A33,'Valores Permitidos Digital'!$5:$5,0),4), "1", "5" ), "Valores Permitidos" ), "-" ) -> Valores Permitidos
A34: ft_location_description | B34: string | C34: Essa coluna será renomeada para 'ft_region_extra'. Será um campo de preenchimento adicional para casos nas quais houver necessidade de identificação de composição de região. | D34: SIM | E34: Sem exceções
A35: ft_tiktokdirect_hashtag_campaign | B35: string | C35: Coluna usada para mostrar os URL'S dos criativos. | E35: Preenchimento nulo aceito quando não há o URL do criativo.
A36: ft_video_seconds | B36: string | C36: Duração do criativo em segundos (ex.: 6s, 15s, 30s etc...). | D36: SIM | E36: 'novideo' quando não aplicável.
A37: ft_video_seconds_group10 | B37: string | C37: Faixa de duração do vídeo agrupada em classificações de 10s (ex.: until_6s, 7s_to_15s, 16s_to_20s, 21s_to_30s, others). | D37: SIM | E37: Sem exceções | F37: =IFERROR( HYPERLINK( "#'Valores Permitidos Digital'!" & SUBSTITUTE( ADDRESS(1,MATCH(A37,'Valores Permitidos Digital'!$5:$5,0),4), "1", "5" ), "Valores Permitidos" ), "-" ) -> Valores Permitidos
A38: ft_video_seconds_group30 | B38: string | C38: Faixa de duração do vídeo agrupada em classificações de até 30s (ex.: until_6s, 7s_to_15s, 16s_to_30s, 31s_to_60s, 61s_to_120s, others). | E38: Sem exceções | F38: =IFERROR( HYPERLINK( "#'Valores Permitidos Digital'!" & SUBSTITUTE( ADDRESS(1,MATCH(A38,'Valores Permitidos Digital'!$5:$5,0),4), "1", "5" ), "Valores Permitidos" ), "-" ) -> Valores Permitidos
A39: gl_age_lower_upper | B39: string | C39: Faixa etária mínima e máxima do público-alvo da campanha (ex.: 18+, 25+, 18-44, 25-44 etc...). | E39: Sem exceções
A40: gl_audience_gender | B40: string | C40: Gênero do público-alvo (ex.: f=feminino, ad=todos/adulto). | E40: Sem exceções | F40: =IFERROR( HYPERLINK( "#'Valores Permitidos Digital'!" & SUBSTITUTE( ADDRESS(1,MATCH(A40,'Valores Permitidos Digital'!$5:$5,0),4), "1", "5" ), "Valores Permitidos" ), "-" ) -> Valores Permitidos
A41: gl_audience_name | B41: string | C41: Nome da audiência usada para segmentação. Campo livre a partir de 2026. | E41: Campo livre
...

Sheet Valores Permitidos Digital
A1: Valores Permitidos Digital | B1: Voltar Menu
B3: media type | C3: Digital | M3: media type | N3: Digital
A5: bd_extraction_source | B5: bd_platform | D5: ft_ad_objective | E5: ft_brand_lift | F5: ft_directdeal_type | G5: ft_format_type_local | H5: ft_formataggregated | I5: ft_influencer_brand | J5: ft_region | K5: ft_location_type | L5: ft_placement_type_local | M5: ft_publisher | O5: ft_video_seconds_group10 | P5: ft_video_seconds_group30 | Q5: gl_audience_gender | R5: gl_audience_party | S5: ft_audience_type | T5: gl_brand_name | U5: gl_buy_model | V5: gl_buy_type | W5: gl_campaign_objective | X5: gl_country_code | Y5: gl_destination_retailer | Z5: gl_device_type | AA5: gl_format_type | AB5: gl_influencer | AC5: gl_influencer_post_type | AD5: gl_keyword_match | AE5: gl_keyword_type | AF5: gl_landing_page_type | AG5: gl_meta_collab_ad | AH5: gl_placement_type | AI5: gl_product_subcategory | AJ5: tx_unilever_division
A6: api | B6: 365Scores | D6: recal | E6: brdlft-n | F6: cache (descontinuado) | G6: AdColony | H6: audio | I6: brand | J6: nac | K6: estado | L6: appcamp | M6: 365Scores | O6: 16s_to_20s | P6: 16s_to_30s | Q6: Ad | R6: 1pd-dad | S6: Behav | T6: ala | U6: OMP | V6: CPA | W6: adv | X6: br | Y6: 7-Eleven | Z6: All | AA6: Carousel | AB6: BSAY | AC6: BSTD | AD6: BM | AE6: BrndProd | AF6: Brand | AG6: collab | AH6: ContSug | AI6: AIR | AJ6: bw
A7: compra direta | B7: Abril | D7: apeve | E7: brdlft-y | F7: conteudo/cache/producao (descontinuado) | G7: Ad-Sequence | H7: display | I7: influencer | J7: reg-no | K7: cidade | L7: audevrynoskp | M7: 99 | O7: 21s_to_30s | P7: 31s_to_60s | Q7: F | R7: 1pd-did | S7: CollPform | T7: all-things-hair | U7: OMPPMP | V7: CPC | W7: con | Y7: A-101 | Z7: CTV | AA7: Collect | AB7: IHAMP | AC7: DARK | AD7: DSA | AE7: Comp | AF7: Cat | AG7: nocollab | AH7: DCODisp | AI7: AIRFRSH | AJ7: cp
B8: Amazon | D8: apeve | F8: midia | G8: AppCard | H8: texto | I8: ugc | J8: reg-ne | K8: regiao | L8: audevryskp | M8: Abril | O8: 31s_to_40s | P8: 61s_to_120s | Q8: M | R8: 1pd-diddad | S8: CombAud | T8: axe | U8: PMP | V8: CPI | W8: Inf | Y8: AB | Z8: Desk | AA8: DyProd | AB8: BHAMP | AC8: NA | AD8: DSAB | AE8: DSA | AF8: D2C | AH8: DCOVid | AI8: BWPROFHAIR | AJ8: hc
B9: AmazonAds | D9: brcon | G9: Arroba | H9: video | J9: reg-co | K9: nacional | L9: bngead | M9: Adsmovil | O9: 41s_to_50s | P9: 7s_to_15s | R9: no1pd | S9: CRM | T9: baby-dove | U9: Prefer | V9: CPL | W9: Ins | Y9: ADEG | Z9: DigOOH | AA9: EventResp | AD9: DSABE | AE9: Gen | AF9: Ext | AH9: OOHDisp | AI9: BWPROFSKNCR | AJ9: ic
B10: AmazonDSP | D10: calls | G10: Audio | J10: reg-se | L10: beffect | M10: Agência Dino | O10: 51s_to_60s | P10: more_than_120s | S10: Cust | T10: ben-&-jerrys (descontinuado) | U10: ProgGuar | V10: CPM | W10: awa | Y10: Aeon | Z10: Game | AA10: Image | AD10: DSABPE | AE10: GenProd | AF10: None | AH10: OOHVid | AI10: BWUND | AJ10: nt
B11: Aqueles Caras | D11: casal | G11: Billboard | J11: reg-su | L11: bmission | M11: Agita Caruaru | O11: 61s_to_120s | P11: novideo | S11: Demog | T11: brilhante | U11: GooglePref | V11: CPV | W11: awacons | Y11: AH | Z11: Mob | AA11: InstExp | AD11: DSABP | AE11: BrndGen | AF11: Retail | AH11: EcomResp | AI11: BEVUND | AJ11: pc
B12: CyberCook | D12: click | G12: Bumper | J12: est-ac | L12: bump | M12: Alexa | O12: 7s_to_15s | P12: until_6s | S12: DMP | T12: cif | U12: TrVAction | V12: 1stImp | W12: cons | Y12: Ahold | Z12: MobDesk | AA12: LeadGen | AD12: DSAE | AE12: Brand | AF12: Retail-Mikmak | AH12: InBanVid | AI12: BOUSEA
B13: Dgmax | D13: talks | G13: Canvas | J13: est-al | L13: bumptfnonskip | M13: Amazon Search | O13: more_than_120s | S13: InMark | T13: cleanipedia | U13: TrVAuc | V13: Ffee | W13: conv | Y13: Airlift | Z13: MobTab | AA13: Offer | AD13: DSAP | AE13: Comb | AF13: Stp | AH13: InFeed | AI13: CBMMEAL
B14: Disney | D14: conve | G14: Carrossel | J14: est-ap | L14: bumptfskip | M14: AmazonAds | O14: novideo | S14: InmLst | T14: clear | U14: TrVReach | V14: vCPM | Y14: Albert | Z14: MobDeskTab | AA14: Sshow | AD14: DSAPE | AF14: Socl | AH14: InRead | AI14: CRLS
B15: DV360 | D15: macon | G15: Cinemagraph | J15: est-am | L15: cuttedge | M15: AmazonDSP | O15: until_6s | S15: IntAff | T15: close-up | U15: TrVInsRes | V15: ZCost | Y15: Albertsons | Z15: SmSpeak | AA15: Stories | AD15: EM | AF15: TTS | AH15: InStream | AI15: COFFEE
B16: Futbol Sites | D16: marev | G16: Collection | J16: est-ba | L16: dgen | M16: Aqueles Caras | S16: Lstyle | T16: comfort | U16: OpAuc | Y16: Alcampo | Z16: Tab | AA16: Vid | AD16: EMB | AH16: Interstit | AI16: COLR
B17: Gamers Club | D17: secon | G17: ConversationalCard | J17: est-ce | L17: dstqprgplay | M17: BabyCenter | S17: LLike | T17: dove | U17: ReaFreq | Y17: Aldi | AA17: AppCard | AD17: EMBP | AH17: MixOut | AI17: OTCNDUND
B18: Glamour | D18: smcon | G18: Direct-Message-Card | J18: est-df | L18: diariadsply | M18: Band | S18: None | T18: dove-men+care | U18: Reserv | Y18: Alfacart | AA18: ConCard | AD18: EMP | AH18: Multi | AI18: CKAID
B19: Globo | D19: ttscl | G19: Display | J19: est-es | L19: eymx | M19: Bing | S19: Rmkt | T19: fofo | U19: Auc | Y19: Alfamart | AA19: DMCard | AD19: PM | AH19: RwdDisp | AI19: COSMT
B20: Google Ads | D20: ttsch | G20: DOOH-Display | J20: est-go | L20: fed-dply | M20: Bloco de Rua | T20: gelartier (descontinuado) | Y20: Aliexpress | AA20: 1stView | AD20: PMB | AH20: RwdVid | AI20: CREAMS
B21: Hypr | D21: ttspu | G21: DOOH-Video | J21: est-ma | L21: fed-stor | M21: Camisa23 | T21: hellmanns | Y21: Allegro | AA21: PromAc | AD21: EM | AH21: RichMedDisp | AI21: DEO
B22: iFood Ads | D22: ttsre | G22: Dynamic | J22: est-mt | L22: fed-stor-reel | M22: Carrefour | T22: kibon (descontinuado) | Y22: All-Things-Hair | AA22: ProMom | AD22: BM | AH22: RbkTkover | AI22: DEOFGRUND
B23: IMMakers | D23: conve | G23: Event | J23: est-ms | L23: feednskp | M23: Cartola | T23: knorr | Y23: Altex | AA23: PromPoll | AD23: NA | AH23: SttBan | AI23: DESSRT
B24: Impulso | D24: darea | G24: event-response | J24: est-mg | L24: feedskp | M24: ChatGPT | T24: liquid i.v | Y24: Alza | AA24: Video | AD24: NB | AH24: Spons | AI24: DSHWSH
B25: Kwai | D25: event | G25: Feed | J25: est-pa | L25: fstscradtl | M25: Criteo | T25: love-beauty-and-planet | Y25: AmazonCore | AA25: WebCard | AH25: StdDisp | AI25: FABCLN
B26: Lancenet | D26: impre | G26: FirstView | J26: est-pb | L26: fstscrimmplus | M26: CyberCook | T26: lux | Y26: AmazonFresh | AA26: SnapAds | AH26: TopView | AI26: FABENH
B27: LeadMedia | D27: insta | G27: Fullbanner | J27: est-pr | L27: fstscrimmmast | M27: Daki | T27: mae-terra | Y27: AmazonPantry | AA27: SnapLens | AH27: TrackPlac | AI27: FACE
B28: Logan | D28: inter | G28: GIF | J28: est-pe | L28: framegplay | M28: DAZN | T28: magnum (descontinuado) | Y28: AmazonPrimeNow | AA28: SnapStor | AH28: Bump | AI28: FOODUND
B29: Mercado Ads | D29: focom | G29: halfbanner | J29: est-pi | L29: instm-nskipyt | M29: Dgmax | T29: maizena | Y29: Americanas | AA29: SponFilt | AH29: CompBan | AI29: FRGRNC
B30: Meta | D30: vicom | G30: Halfpage | J30: est-rj | L30: inoutnoskp | M30: Discovery | T30: nexxus | Y30: Amici | AA30: Aud | AH30: Disc | AI30: FUNHYD
B31: N Sports | D31: leads | G31: html | J31: est-rn | L31: inoutskp | M31: Disney Plus | T31: omo | Y31: Apollo | AA31: Disp | AH31: EfReach | AI31: HAIRUND
B32: Netflix | D32: licli | G32: Image | J32: est-rs | L32: instm-skipyt | M32: DV360-Programmatic | T32: recepedia | Y32: ApolloPharmacy | AA32: NatDisp | AH32: InFeedVid | AI32: HBCARE
B33: One Football | D33: macli | G33: InfeedAds | J33: est-ro | L33: mscogplay | M33: Equativ | T33: rexona | Y33: Arenal | AA33: NatVid | AH33: InStr | AI33: H&HUND
B34: One Stop | D34: malea | G34: InstantExperience | J34: est-rr | L34: Multi | M34: ESPN | T34: seda | Y34: Arpico | AA34: Email | AH34: Mhead | AI34: HCUND
B35: PagueMenos | D35: matra | G35: instant-experiences | J35: est-sc | L35: ntvdsply | M35: Estadao | T35: suave | Y35: ASDA | AA35: SCwP | AH35: NSkip | AI35: HOTSAU
B36: Pinterest | D36: messa | G36: Landscape | J36: est-sp | L36: ntvnoskp | M36: Etermax | T36: surf | Y36: Astro | AA36: ShopPLA | AH36: NonSkipInStr | AI36: HHCLN
... B40: RelevanC | D40: reach | G40: Message | J40: cid-rio | L40: pmax | M40: Football Co | T40: vim | Y40: BachHoaXanh | AA40: SponBrand | AH40: Feed | AI40: INTSNCKSOUP
B41: SamsungAds | D41: refre | G41: Mobile-Banner | J41: cid-brb | L41: primgplay | M41: Futbol Sites | Y41: Bagallery | AA41: SponDisp | AH41: FeedStory | AI41: KTCHP
B42: SBT | D42: rknsk | G42: MobileWidebanner | J42: cid-ssa | L42: reel | M42: G1 | Y42: Banabi | AA42: SponProd | AH42: FeedReel | AI42: LFINTEA
B43: ShowHeroes | D43: rfski | G43: MobVertical | J43: cid-for | L43: reels-stor | M43: Gama | Y43: Barbora | AA43: SponBV | AH43: FeedStoryReel | AI43: LIFENTR
B44: Spotify | D44: rensk | G44: Moments | J44: cid-bhz | L44: rwdnoskip | M44: Gamers Club | Y44: Bazar365 | AA44: SponBPC | AH44: In-Artic | AI44: LQDS
B45: Stealthelook | D45: reski | G45: N-A | J45: cid-mao | L45: rwrdskp | M45: GE | Y45: Bazzar | AA45: SponBSS | AH45: Message | AI45: MAYO
...

Sheet Regras e Combinações Digital
A1: Media Inventory | C1: Voltar Menu
B3: media type | C3: Digital
X4: * para além dos publisher listados, considerar os valores listado sem o publisher atribuido
B5: bd platform | C5: vehicle name | E5: ft_influencer_brand | F5: gl_influencer | H5: Media Vehicle | I5: Placement Local | J5: Placement Global | K5: Video Skip Type | L5: Format Type | N5: Division | O5: Brand Name | P5: Market Name (PCAT) | R5: gl_buy_model | S5: ft_publisher | U5: bd_plarform type | V5: gl_campaing_objective | X5: ft_publisher | Y5: gl_format_type
B6: 365Scores | C6: 365Scores | E6: brand | F6: BSAY | H6: Amazon Search | I6: Search | J6: Search | K6: No Video | L6: Sponsored Brands | N6: bw | O6: All Things Hair | P6: Beauty & Wellbeing Unidentified | R6: OMP | S6: AmazonDSP | U6: search | V6: adv | X6: Facebook | Y6: Carousel | AA6: media type | AB6: Digital
B7: Abril | C7: Abril | E7: influencer | F7: IHAMP | H7: Amazon Search | I7: Search | J7: Search | K7: No Video | L7: Sponsored Display | N7: bw | O7: Clear | P7: Wash & Care | R7: OMP | S7: Dgmax | U7: search | V7: con | X7: Facebook | Y7: Collect
B8: Amazon | C8: Amazon Search | E8: influencer | F8: BHAMP | H8: Amazon Search | I8: Search | J8: Search | K8: No Video | L8: Sponsored Products | N8: bw | O8: Dove | P8: Wash & Care | R8: OMP | S8: Hypr | U8: search | V8: Inf | X8: Facebook | Y8: DyProd | AA8: bd platform | AB8: vehicle name
B9: Amazon | C9: AmazonAds | E9: ugc | F9: IHAMP | H9: Amazon Search | I9: Search | J9: Search | K9: No Video | L9: Sponsored Brand Video | N9: bw | O9: Liquid IV | P9: Functional Hydration | R9: OMP | S9: IMMakers | U9: search | V9: Ins | X9: Facebook | Y9: EventResp | AA9: 365Scores | AB9: 365Scores
B10: Amazon | C10: AmazonDSP | E10: ugc | F10: BHAMP | H10: Amazon Search | I10: Search | J10: Search | K10: No Video | L10: Sponsored Brand Product Collection | N10: bw | O10: Nexxus | P10: Wash & Care | R10: OMP | S10: Logan | U10: audio | V10: Awa | X10: Facebook | Y10: Image | AA10: Abril | AB10: Abril
B11: Amazon | C11: Prime Video Ads | H11: Amazon Search | I11: Search | J11: Search | K11: No Video | L11: Sponsored Brand Store Spotlight | N11: bw | O11: Seda | P11: Wash & Care | R11: OMP | S11: VI Media | U11: audio | V11: AwaCons | X11: Facebook | Y11: InstExp | AA11: Amazon | AB11: Amazon Search
B12: Amazon | C12: Twitch | H12: Direto | I12: CuttingEdge-Display | J12: Roadblock/Takeover | K12: No Video | L12: Display | N12: bw | O12: TRESemme | P12: Wash & Care | R12: OMP | S12: Weach | U12: audio | V12: Cons | X12: Facebook | Y12: LeadGen | AA12: Amazon | AB12: AmazonAds
B13: AmazonAds | C13: AmazonAds | H13: Direto | I13: Destaque-Premium-Globoplay-Display | J13: Standard Display | K13: No Video | L13: Display | N13: cp | O13: Unilever Brand Range | P13: Home Care Unidentified | R13: OMP | S13: DV360-Programmatic | U13: audio | V13: Conv | X13: Facebook | Y13: Offer | AA13: Amazon | AB13: AmazonDSP
B14: AmazonDSP | C14: AmazonDSP | H14: Direto | I14: Diaria-Display | J14: Standard Display | K14: No Video | L14: Display | N14: hc | O14: Ala | P14: Fabric Cleaning | R14: OMP | S14: Equativ | U14: connected tv | V14: Awa | X14: Facebook | Y14: Sshow | AA14: Amazon | AB14: Prime Video Ads
B15: Aqueles Caras | C15: Aqueles Caras | H15: Direto | I15: Native-Display | J15: Content Suggestion | K15: No Video | L15: NativeDisplay | N15: hc | O15: Brilhante | P15: Fabric Cleaning | R15: OMP | S15: Magnite | U15: connected tv | V15: AwaCons | X15: Facebook | Y15: Stories | AA15: Amazon | AB15: Twitch
B16: CyberCook | C16: CyberCook | H16: Direto | I16: Native-Video-NonSkippable | J16: Content Suggestion | K16: Non-Skippable | L16: NativeVideo | N16: hc | O16: Cif | P16: Household Cleaning | R16: OMP | S16: Google Ads | U16: connected tv | V16: Cons | X16: Facebook | Y16: Vid | AA16: AmazonAds | AB16: AmazonAds
B17: Dgmax | C17: Dgmax | H17: Direto | I17: Native-Video-Skippable | J17: Content Suggestion | K17: Skippable | L17: NativeVideo | N17: hc | O17: Comfort | P17: Fabric Enhancers | R17: OMP | S17: LeadMedia | U17: connected tv | V17: Conv | X17: meta | Y17: Carousel | AA17: AmazonDSP | AB17: AmazonDSP
B18: Disney | C18: Disney Plus | H18: Direto | I18: Push-Notification | J18: Standard Display | K18: No Video | L18: Display | N18: hc | O18: Fofo | P18: Fabric Enhancers | R18: OMPPMP | S18: AmazonDSP | U18: gaming | V18: Awa | X18: meta | Y18: Collect | AA18: Aqueles Caras | AB18: Aqueles Caras
B19: DV360 | C19: DV360-Programmatic | H19: Direto | I19: Rewarded-Video-NonSkippable | J19: Rewarded Video | K19: Non-Skippable | L19: Video | N19: hc | O19: Omo | P19: Fabric Cleaning | R19: OMPPMP | S19: Dgmax | U19: gaming | V19: AwaCons | X19: meta | Y19: DyProd | AA19: CyberCook | AB19: CyberCook
B20: DV360 | C20: Equativ | H20: Direto | I20: Rewarded-Video-Skippable | J20: Rewarded Video | K20: Skippable | L20: Video | N20: hc | O20: Surf | P20: Fabric Cleaning | R20: OMPPMP | S20: Hypr | U20: gaming | V20: Cons | X20: meta | Y20: EventResp | AA20: Dgmax | AB20: Dgmax
B21: DV360 | C21: Magnite | H21: Direto | I21: RichMedia-Display | J21: Rich Media Display | K21: No Video | L21: Display | N21: hc | O21: Unilever Professional | P21: Professional Fabric Cleaning | R21: OMPPMP | S21: IMMakers | U21: gaming | V21: Conv | X21: meta | Y21: Image | AA21: Disney | AB21: Disney Plus
B22: DV360 | C22: Netflix | H22: Direto | I22: Standard-Display-IAB | J22: Standard Display | K22: No Video | L22: Display | N22: hc | O22: Vim | P22: Household Cleaning | R22: OMPPMP | S22: Logan | U22: news/content portals | V22: Awa | X22: meta | Y22: InstExp | AA22: DV360 | AB22: DV360-Programmatic
... B41: iFood Ads | C41: IFood Ads | H41: Facebook | I41: Stories | J41: in-Feed | K41: Skippable | L41: lead generation | N41: pc | O41: Dove | P41: Deodorants | R41: PMP | S41: LeadMedia | U41: service app | V41: Conv | X41: instagram | Y41: DyProd | AA41: Google Ads | AB41: Google Search
B42: IMMakers | C42: IMMakers | H42: Facebook | I42: Reels-Stories | J42: in-Feed | K42: Skippable | L42: lead generation | R42: Prefer | S42: AmazonDSP | U42: social | V42: Awa | X42: instagram | Y42: EventResp | AA42: Google Ads | AB42: Youtube
B43: Impulso | C43: Impulso | H43: Facebook | I43: Feed-Stories | J43: in-Feed | K43: Skippable | L43: lead generation | R43: Prefer | S43: Dgmax | U43: social | V43: AwaCons | X43: instagram | Y43: Image | AA43: Hypr | AB43: Hypr
B44: Kwai | C44: Kwai | H44: Facebook | I44: Feed-Stories-Reels | J44: in-Feed | K44: Skippable | L44: lead generation | R44: Prefer | S44: Hypr | U44: social | V44: Cons | X44: instagram | Y44: InstExp | AA44: iFood Ads | AB44: IFood Ads
B45: Lancenet | C45: Lancenet | H45: Facebook | I45: Feed-Video-NonSkippable | J45: in-Feed | K45: Skippable | L45: lead generation | R45: Prefer | S45: IMMakers | U45: social | V45: Conv | X45: instagram | Y45: LeadGen | AA45: IMMakers | AB45: IMMakers
B46: LeadMedia | C46: LeadMedia | H46: Facebook | I46: Feed-Video-Skippable | J46: in-Feed | K46: Skippable | L46: lead generation | R46: Prefer | S46: Logan | U46: streaming | V46: Awa | X46: instagram | Y46: Offer | AA46: Impulso | AB46: Impulso
B47: Logan | C47: Logan | H47: Facebook | I47: Reels | J47: in-Feed | K47: Skippable | L47: lead generation | R47: Prefer | S47: VI Media | U47: streaming | V47: AwaCons | X47: instagram | Y47: Sshow | AA47: Kwai | AB47: Kwai
B48: Mercado Ads | C48: AmazonDSP | H48: Globo | I48: Binge-Ads-Display | J48: in-Stream | K48: No Video | L48: Display | R48: Prefer | S48: Weach | U48: streaming | V48: Cons | X48: instagram | Y48: Stories | AA48: Lancenet | AB48: Lancenet
B49: Mercado Ads | C49: Mercado Livre | H49: Globo | I49: FrameAds-Globoplay-Display | J49: in-Stream | K49: No Video | L49: Display | R49: Prefer | S49: DV360-Programmatic | U49: streaming | V49: Conv | X49: instagram | Y49: Vid | AA49: LeadMedia | AB49: LeadMedia
B50: Meta | C50: Facebook | H50: Globo | I50: Mosaico-Globoplay-Display | J50: in-Stream | K50: No Video | L50: Display | R50: Prefer | S50: Equativ | X50: Twitter | Y50: AppCard | AA50: Logan | AB50: Logan
B51: Meta | C51: Instagram | H51: Globo | I51: PauseAds-Globoplay-Display | J51: in-Stream | K51: No Video | L51: Display | R51: Prefer | S51: Magnite | X51: Twitter | Y51: ConCard | AA51: Mercado Ads | AB51: AmazonDSP
B52: Meta | C52: Meta | H52: Globo | I52: PauseAds-Skippable | J52: in-Stream | K52: Skippable | L52: Display | R52: Prefer | S52: Google Ads | X52: Twitter | Y52: DMCard | AA52: Mercado Ads | AB52: Mercado Livre
B53: Meta | C53: Threads | H53: Globo | I53: Primeirissima-Globoplay-Skippable | J53: in-Stream | K53: Skippable | L53: Video | R53: Prefer | S53: LeadMedia | X53: Twitter | Y53: 1stView | AA53: Meta | AB53: Facebook
B54: N Sports | C54: N Sports | H54: Globo | I54: Segundissima-Globoplay-Skippable | J54: in-Stream | K54: Skippable | L54: Video | R54: ProgGuar | S54: AmazonDSP | X54: Twitter | Y54: Image | AA54: Meta | AB54: Instagram
B55: Netflix | C55: Netflix | H55: Google Ads | I55: Bumper-TargetFrequency-Skippable | J55: in-Stream | K55: Skippable | L55: Video | R55: ProgGuar | S55: Dgmax | X55: Twitter | Y55: PromAc | AA55: Meta | AB55: Meta
B56: One Football | C56: One Football | H56: Google Ads | I56: Bumper-TargetFrequency-Skippable | J56: in-Stream | K56: Skippable | L56: Video | R56: ProgGuar | S56: Hypr | X56: Twitter | Y56: ProMom | AA56: Meta | AB56: Threads
B57: One Stop | C57: One Stop | H57: Google Ads | I57: FirstScreenAdTile-Dynamic | J57: In-Banner Video | K57: Dynamic | L57: Video | R57: ProgGuar | S57: IMMakers | X57: Twitter | Y57: PromPoll | AA57: N Sports | AB57: N Sports
B58: PagueMenos | C58: Vtex | H58: Google Ads | I58: FirstScreenImmersivePlus-Dynamic | J58: In-Banner Video | K58: Dynamic | L58: Video | R58: ProgGuar | S58: Logan | X58: Twitter | Y58: Video | AA58: Netflix | AB58: Netflix
B59: Pinterest | C59: Pinterest | H59: Google Ads | I59: FirstScreenImmesiveMasthead-Dynamic | J59: In-Banner Video | K59: Dynamic | L59: Video | R59: ProgGuar | S59: VI Media | X59: Twitter | Y59: WebCard | AA59: One Football | AB59: One Football
...

Sheet Dicionário de Dados Offline
A1: Dicionário Offline | B1: Voltar Menu
A3: Nome da Coluna | B3: Tipo do Dado | C3: Descrição | D3: RROI | E3: Permissões de Preenchimento | F3: Lista
A4: Brand | B4: string | C4: Marca anunciante associada à veiculação offline | D4: SIM | E4: Sem exceções | F4: =IFERROR( HYPERLINK( "#'Valores Permitidos Offline'!" & SUBSTITUTE( ADDRESS(1,MATCH(A4,'Valores Permitidos Offline'!$4:$4,0),4), "1", "3" ), "Valores Permitidos" ), "-" ) -> Valores Permitidos
A5: Campaign_Name | B5: string | C5: Nome da campanha, composto por CN Code e Nome conforme cadastro global. | D5: SIM | E5: Sem exceções
A6: Channel_Name | B6: string | C6: Nome do veículo onde a mídia foi veiculada. | D6: SIM | E6: Sem exceções
A7: Channel_Representative | B7: string | C7: Representante comercial, grupo de mídia ou empresa responsável pela comercialização do canal/veículo informado na linha. | E7: Sem exceções
A8: Creative_Length | B8: string | C8: Duração ou formato principal do criativo/inserção. Em TV pode indicar secundagem; em outros meios pode indicar formatos como DOOH, Social, Compra Direta, jornais, entre outros. | D8: SIM | E8: Sem exceções | F8: =IFERROR( HYPERLINK( "#'Valores Permitidos Offline'!" & SUBSTITUTE( ADDRESS(1,MATCH(A8,'Valores Permitidos Offline'!$4:$4,0),4), "1", "3" ), "Valores Permitidos" ), "-" ) -> Valores Permitidos
A9: Creative_Title | B9: string | C9: Título, nome ou identificação do criativo/peça utilizada na veiculação. | D9: SIM | E9: Sem exceções
A10: Division | B10: string | C10: Divisão ou unidade de negócio da Unilever responsável pela marca/campanha, como Home Care, Personal Care... | D10: SIM | E10: Sem exceções | F10: =IFERROR( HYPERLINK( "#'Valores Permitidos Offline'!" & SUBSTITUTE( ADDRESS(1,MATCH(A10,'Valores Permitidos Offline'!$4:$4,0),4), "1", "3" ), "Valores Permitidos" ), "-" ) -> Valores Permitidos
A11: Flight_Info | B11: string | C11: Informações complementares sobre o flight, período, pacote ou janela de entrega da veiculação. Pode conter identificação do pacote comercial quando aplicável. | E11: Sem exceções | F11: =IFERROR( HYPERLINK( "#'Valores Permitidos Offline'!" & SUBSTITUTE( ADDRESS(1,MATCH(A11,'Valores Permitidos Offline'!$4:$4,0),4), "1", "3" ), "Valores Permitidos" ), "-" ) -> Valores Permitidos
A12: insertion_date | B12: date | C12: Data da veiculação da mídia. Deve representar o dia efetivo utilizado para granularidade diária da base. | D12: SIM | E12: Sem exceções
A13: Insertion_Order_Number | B13: string | C13: Número da ordem de inserção da compra de mídia. Usado para rastrear o contrato ou pedido associado à linha. | E13: Sem exceções
A14: Insertion_Order_Type | B14: string | C14: Tipo da ordem de inserção ou condição de faturamento/execução da mídia, como normal, bonificação, reaplicação ou pagamento antecipado. | E14: Sem exceções | F14: =IFERROR( HYPERLINK( "#'Valores Permitidos Offline'!" & SUBSTITUTE( ADDRESS(1,MATCH(A14,'Valores Permitidos Offline'!$4:$4,0),4), "1", "3" ), "Valores Permitidos" ), "-" ) -> Valores Permitidos
A15: Insertion_Show_Time | B15: bigint | C15: Horário efetivo da inserção dentro do programa ou faixa, quando aplicável. | E15: Preenchimento nulo (vazio) permitido quando não aplicável. | F15: =IFERROR( HYPERLINK( "#'Valores Permitidos Offline'!" & SUBSTITUTE( ADDRESS(1,MATCH(A15,'Valores Permitidos Offline'!$4:$4,0),4), "1", "3" ), "Valores Permitidos" ), "-" ) -> Valores Permitidos
A16: Insertion_Type | B16: string | C16: Classificação do tipo de inserção/comercialização da mídia, como regular, patrocínio, programático, social, compra direta ou outro formato operacional. | D16: SIM | E16: Sem exceções | F16: =IFERROR( HYPERLINK( "#'Valores Permitidos Offline'!" & SUBSTITUTE( ADDRESS(1,MATCH(A16,'Valores Permitidos Offline'!$4:$4,0),4), "1", "3" ), "Valores Permitidos" ), "-" ) -> Valores Permitidos
A17: Media_Subtype | B17: string | C17: Subtipo de mídia no nível mais detalhado da classificação, como Paid Social Video, Dynamic OOH, Digital Audio Streaming, Newspapers, Native Video, entre outros. | E17: Sem exceções | F17: =IFERROR( HYPERLINK( "#'Valores Permitidos Offline'!" & SUBSTITUTE( ADDRESS(1,MATCH(A17,'Valores Permitidos Offline'!$4:$4,0),4), "1", "3" ), "Valores Permitidos" ), "-" ) -> Valores Permitidos
A18: Media_Target | B18: string | C18: Público-alvo de mídia utilizado na compra ou avaliação da peça. | D18: SIM | E18: Sem exceções | F18: =IFERROR( HYPERLINK( "#'Valores Permitidos Offline'!" & SUBSTITUTE( ADDRESS(1,MATCH(A18,'Valores Permitidos Offline'!$4:$4,0),4), "1", "3" ), "Valores Permitidos" ), "-" ) -> Valores Permitidos
A19: Media_Type | B19: string | C19: Tipo principal de mídia/ambiente de veiculação, como TV Paga, Social, OOH, Digital Audio, Digital Video, Print, Radio ou Other Digital. | D19: SIM | E19: Sem exceções | F19: =IFERROR( HYPERLINK( "#'Valores Permitidos Offline'!" & SUBSTITUTE( ADDRESS(1,MATCH(A19,'Valores Permitidos Offline'!$4:$4,0),4), "1", "3" ), "Valores Permitidos" ), "-" ) -> Valores Permitidos
A20: Month_year | B20: string | C20: Mês de competência da veiculação no formato ano-mês. Usado para análises mensais e conciliação com investimento. | D20: SIM | E20: Sem exceções
A21: MT_Net_Investment | B21: double | C21: Investimento líquido da mídia, já considerando negociações, descontos ou condições comerciais aplicáveis. | D21: SIM | E21: Valores nulos aceitos (0, blank)
A22: MT_Non_Negotiated_Investment | B22: double | C22: Investimento não negociado/bruto da mídia, antes de negociações ou descontos aplicados. Campo monetário de referência comercial. | E22: Valores nulos aceitos (0, blank)
A23: MT_Show_Audience_DayAvg_Absolute_Individuals | B23: double | C23: Audiência absoluta média diária em indivíduos para o programa/faixa/veiculação, quando aplicável à mídia de audiência. | E23: Valores nulos aceitos (0, blank)
A24: MT_Show_Audience_DayAvg_Absolute_Target | B24: double | C24: Audiência absoluta média diária no target principal da campanha para o programa/faixa/veiculação. | E24: Valores nulos aceitos (0, blank)
A25: MT_Show_Audience_DayAvg_Absolute_Target_Secondary | B25: bigint | C25: Audiência absoluta média diária no target secundário da campanha, quando houver mensuração adicional. | E25: Valores nulos aceitos (0, blank)
A26: MT_Show_Audience_DayAvg_GRP | B26: double | C26: GRP médio diário do programa/faixa/veiculação no público avaliado. Métrica típica de TV e meios com mensuração de audiência. | D26: SIM | E26: Valores nulos aceitos (0, blank)
A27: MT_Show_Audience_DayAvg_GRP_PondNet_30s | B27: float | C27: GRP médio diário ponderado/net equivalente a 30 segundos, utilizado para padronização de audiência conforme duração da peça. | E27: Valores nulos aceitos (0, blank)
A28: MT_Show_Audience_DayAvg_TRP | B28: double | C28: TRP médio diário do programa/faixa/veiculação no target principal da campanha. | E28: Valores nulos aceitos (0, blank)
A29: MT_Show_Audience_DayAvg_TRP_PondNet_30s | B29: float | C29: TRP médio diário ponderado/net equivalente a 30 segundos, usado para comparação padronizada entre inserções com durações diferentes. | E29: Valores nulos aceitos (0, blank)
A30: MT_Show_Audience_DayAvg_TRP_Secondary | B30: double | C30: TRP médio diário para o target secundário, quando a campanha possuir avaliação adicional de audiência. | E30: Valores nulos aceitos (0, blank)
A31: Package_Info | B31: string | C31: Descrição do pacote comercial, projeto especial, patrocínio, plano ou agrupamento de compra relacionado à inserção. | E31: Campo de preenchimento livre | F31: =IFERROR( HYPERLINK( "#'Valores Permitidos Offline'!" & SUBSTITUTE( ADDRESS(1,MATCH(A31,'Valores Permitidos Offline'!$4:$4,0),4), "1", "3" ), "Valores Permitidos" ), "-" ) -> -
A32: Product_Subcategory | B32: string | C32: Subcategoria do produto associada à marca/campanha, como Fabric Cleaning, Hair Care, Skin Cleansing, Condiments, Deodorants & Fragrances, entre outras. | D32: SIM | E32: Sem exceções | F32: =IFERROR( HYPERLINK( "#'Valores Permitidos Offline'!" & SUBSTITUTE( ADDRESS(1,MATCH(A32,'Valores Permitidos Offline'!$4:$4,0),4), "1", "3" ), "Valores Permitidos" ), "-" ) -> Valores Permitidos
A33: Region | B33: string | C33: Localidade, praça, região ou cobertura geográfica da veiculação, como Nacional, São Paulo, Rio de Janeiro ou outras praças de entrega. | D33: SIM | E33: Sem exceções | F33: =IFERROR( HYPERLINK( "#'Valores Permitidos Offline'!" & SUBSTITUTE( ADDRESS(1,MATCH(A33,'Valores Permitidos Offline'!$4:$4,0),4), "1", "3" ), "Valores Permitidos" ), "-" ) -> Valores Permitidos
A34: TV_Show_Daypart | B34: string | C34: Faixa horária/daypart do programa ou inserção, utilizada principalmente para TV e conteúdos com grade horária. Exemplo: 06:00 a 11:59, 23:00 a 05:59. | D34: SIM | E34: Sem exceções | F34: =IFERROR( HYPERLINK( "#'Valores Permitidos Offline'!" & SUBSTITUTE( ADDRESS(1,MATCH(A34,'Valores Permitidos Offline'!$4:$4,0),4), "1", "3" ), "Valores Permitidos" ), "-" ) -> Valores Permitidos
A35: TV_Show_End_Time | B35: bigint | C35: Horário de término do programa ou faixa, quando disponível. Campo usado para contextualizar a veiculação em TV ou conteúdo com grade. | E35: Sem exceções | F35: =IFERROR( HYPERLINK( "#'Valores Permitidos Offline'!" & SUBSTITUTE( ADDRESS(1,MATCH(A35,'Valores Permitidos Offline'!$4:$4,0),4), "1", "3" ), "Valores Permitidos" ), "-" ) -> Valores Permitidos
A36: TV_Show_Name | B36: string | C36: Nome do programa, atração ou conteúdo associado à inserção. Aplicável principalmente a TV, vídeo, conteúdo patrocinado e formatos de programação. | D36: SIM | E36: Sem exceções
A37: TV_Show_Start_Time | B37: bigint | C37: Horário de início do programa ou faixa, quando disponível. Campo usado para contextualizar a veiculação em TV ou conteúdo com grade. | D37: SIM | E37: Sem exceções | F37: =IFERROR( HYPERLINK( "#'Valores Permitidos Offline'!" & SUBSTITUTE( ADDRESS(1,MATCH(A37,'Valores Permitidos Offline'!$4:$4,0),4), "1", "3" ), "Valores Permitidos" ), "-" ) -> Valores Permitidos

Sheet Valores Permitidos Offline
A1: Valores Permitidos Offline | B1: Voltar Menu
G2: media type | H2: (Vários itens)
A4: Insertion_Order_Type | B4: Division | C4: Brand | D4: Product_Subcategory | E4: Media_Type | F4: Media_Subtype | G4: Channel_Name | I4: Media_Target | J4: Region | K4: Insertion_Type | L4: Creative_Length | M4: TV_Show_Daypart | N4: TV_Show_Start_Time | O4: TV_Show_End_Time | P4: Insertion_Show_Time | Q4: Flight_Info
A5: BONIFICAÇÃO | B5: BEAUTY & WELLBEING | C5: ALA | D5: CONDIMENTS | E5: ATIVAÇÃO | F5: BROADCAST VIDEO ON DEMAND (BVOD) | G5: [TODAS AS EMISSORAS] | I5: AS AB 18+ | J5: ABAETETUBA | K5: GLOBO IMPACTO | L5: 03S | M5: 06:00 A 11:59 | N5: 1000 | O5: 1000 | P5: -1 | Q5: FLIGHT 1
A6: BONIFICAÇÃO AVULSA | B6: HOME CARE | C6: ALL THINGS HAIR | D6: COOKING AIDS | E6: CINEMA | F6: CINEMA ON-SCREEN ADS | G6: Action Midia | I6: AS AB 18+ CPAY TV | J6: AL-ESTADO | K6: MERCHANDISING | L6: 05S | M6: 12:00 A 17:59 | N6: 1005 | O6: 1035 | P6: 0 | Q6: FLIGHT 2
A7: CANCELA E SUBSTITUI | B7: ICE CREAM (descontinuado) | C7: AXE | D7: DEODORANTS & FRAGRANCES | E7: CONNECTED TV | F7: DIGITAL AUDIO STREAMING | G7: AD+R | I7: AS AB 25+ | J7: ALTAMIRA | K7: PATROCÍNIO | L7: 06S | M7: 18:00 A 20:59 | N7: 1015 | O7: 1100 | P7: 1 | Q7: FLIGHT 3
A8: CRÉDITO | B8: NUTRITION | C8: BABY DOVE | D8: FABRIC CLEANING | E8: DIGITAL (descontinuado) | F8: DIGITAL PARTNERSHIPS | G8: Alto Impacto | I8: AS ABC 18+ | J8: AP-ESTADO | K8: REGULAR | L8: 07S | M8: 21:00 A 22:59 | N8: 1030 | O8: 1110 | P8: 10 | Q8: FLIGHT 4
A9: NORMAL | B9: PERSONAL CARE | C9: BEN & JERRYS (descontinuado) | D9: FABRIC ENHANCERS | E9: DIGITAL AUDIO | F9: DYNAMIC DISPLAY BANNERS | G9: Animal Planet | I9: AS ABC 18+ CPAY TV | J9: APUCARANA | L9: 10S | M9: 23:00 A 05:59 | N9: 1035 | O9: 1130 | P9: 100 | Q9: FLIGHT 5
A10: PAGTO.ANTECIPADO | C10: BRILHANTE | D10: HAIR CARE | E10: DIGITAL DISPLAY | F10: DYNAMIC OOH | G10: AXN | I10: AS ABC 18-34 | J10: ARACAJU | L10: 120S | N10: 1045 | O10: 1140 | P10: 1000 | Q10: FLIGHT 6
A11: PATROCÍNIO | C11: CAFUNE | D11: HOME & HYGIENE | E11: DIGITAL VIDEO | F11: IN STREAM VIDEO | G11: Azul | I11: AS ABC 18-49 | J11: ARACATUBA | L11: 15S | N11: 1100 | O11: 1145 | P11: 1001 | Q11: FLIGHT 7
A12: REAPLICAÇÃO | C12: CIF | D12: ICE CREAM CATEGORY (descontinuado) | E12: OOH | F12: MAGAZINES | G12: Bahia FM | I12: AS ABC 25+ | J12: ARAGUAINA | L12: 180S | N12: 1110 | O12: 1150 | P12: 1002 | Q12: FLIGHT 8
A13: REAPLICAÇÃO AVULSA | C13: CLEANIPEDIA | D13: ORAL CARE | E13: OTHER DIGITAL | F13: NATIVE DISPLAY | G13: Band News | I13: AS ABC 25+ CPAY TV | J13: ARAXA | L13: 196S | N13: 1115 | O13: 1200 | P13: 1003 | Q13: FLIGHT 9
A14: VEICUL.PAGTO.ANTECIP. | C14: CLEAR MEN | D14: OTHER FOODS | E14: PRINT | F14: NATIVE VIDEO | G14: Band Sports | I14: AS ABC 25-49 | J14: ARCOVERDE | L14: 210S | N14: 1130 | O14: 1215 | P14: 1004 | Q14: FLIGHT 10
A15: VEICUL.PAGTO.ANTECIP.DIRETO | C15: CLOSE UP | D15: SKIN CARE | E15: RADIO | F15: NEWSPAPERS | G15: Bandeirantes | I15: AS ABC 35+ | J15: ARIQUEMES | L15: 3000S | N15: 1140 | O15: 1225 | P15: 1005 | Q15: NO FLIGHT
C16: COMFORT | D16: SKIN CLEANSING | E16: RETAIL | F16: OFF RETAILER | G16: Be180 | I16: AS ABCDE 18+ | J16: BA-ESTADO | L16: 30S | N16: 1145 | O16: 1230 | P16: 1006
C17: CREMOGEMA | E17: RETAIL MEDIA (descontinuado) | F17: ON-RETAILER DISPLAY | G17: Canal Bis | I17: AS ABCDE 18-49 | J17: BAGE | L17: 360S | N17: 1150 | O17: 1240 | P17: 1007
C18: DOVE | E18: SEARCH | F18: OTHER DIGITAL | G18: Canal Off | I18: AS CDE 18+ | J18: BALSAS | L18: 45S | N18: 1155 | O18: 1245 | P18: 1008
C19: DOVE MEN+CARE | E19: SOCIAL | F19: On-Retailer Other | G19: Carajas FM | I19: DC ABC 15+ | J19: BARREIRAS | L19: 60S | N19: 1200 | O19: 1250 | P19: 1009
C20: FOFO | E20: TV (descontinuado) | F20: PAID SEARCH | G20: City Sign | I20: DC ABC 15+ CPAY TV | J20: BARUERI | L20: 90S | N20: 1215 | O20: 1300 | P20: 101
C21: FOOD SOLUTIONS | E21: TV ABERTA | F21: PAID SOCIAL DISPLAY | G21: Clear Channel | I21: DC ABC 18+ | J21: BAURU | L21: 997S | N21: 1225 | O21: 1305 | P21: 1010
C22: FORÇA VITAMINA | E22: TV PAGA | F22: PAID SOCIAL VIDEO | G22: Clube FM | I22: DC ABC 25+ | J22: BELEM | L22: ABRIGO DE ONIBUS | N22: 1230 | O22: 1315 | P22: 1011
C23: GELATIER (descontinuado) | F23: PODCASTS | G23: Discovery Channel | I23: DC ABC 35+ | J23: BELO HORIZONTE | L23: ACADEMIAS | N23: 1245 | O23: 1325 | P23: 1012
C24: HELLMANNS | F24: RADIO CONTENT PARTNERSHIP | G24: Discovery Home & Health | I24: DC ABCDE 15+ | J24: BLUMENAU | L24: ADESIVOS DE AUTOMÓVEIS | N24: 1255 | O24: 1330 | P24: 1013
C25: KIBON (descontinuado) | F25: RADIO SPOT AIRTIME | G25: Discovery Kids | I25: DC CDE 15+ | J25: BOA VISTA | L25: ADESIVOS DE SOLO | N25: 1300 | O25: 1340 | P25: 1014
C26: KNORR | F26: SOCIAL COMMERCE | G26: Discovery Science | I26: HH ABC 18-49 | J26: BRAGANCA | L26: AERONAVES | N26: 1305 | O26: 1345 | P26: 1015
C27: LIQUID IV | F27: STATIC DISPLAY BANNERS | G27: Discovery Travel | I27: HH ABC1 4-11 | J27: BRASILIA | L27: AEROPORTO | N27: 1325 | O27: 1355 | P27: 1016
C28: LOVE BEAUTY AND PLANET | F28: STATIC OOH | G28: Discovery Turbo | I28: HH ABCDE 18-49 | J28: CABO FRIO | L28: ASPERSORES | N28: 1330 | O28: 1400 | P28: 1017
C29: LUX | F29: SUBSCRIPTION VIDEO ON DEMAND (SVOD) | G29: Eletromidia | I29: MM AB 18+ | J29: CACHOEIRO DO ITAPEMIRIM | L29: BANCA DE JORNAL | N29: 1340 | O29: 1415 | P29: 1018
C30: MAGNUM (descontinuado) | F30: TV PRODUCT PLACEMENT | G30: Energia 97 FM | I30: MM ABC 18+ | J30: CACOAL | L30: CARRO DE SOM | N30: 1345 | O30: 1420 | P30: 1019
C31: MAIZENA | F31: TV SPONSORSHIP | G31: ESPN | I31: MM ABC 18+ C PAY TV | J31: CAMPINA GRANDE | L31: CINEMA | N31: 1350 | O31: 1430 | P31: 102
C32: MÃE TERRA | F32: TV SPOT AIRTIME | G32: ESPN 2 | I32: MM ABC 18-49 | J32: CAMPINAS | L32: COMPRA DIRETA | N32: 1355 | O32: 1440 | P32: 1020
C33: NEXXUS | G33: ESPN 3 | I33: MM ABC 25+ | J33: CAMPOS | L33: CONNECTED TV | N33: 1400 | O33: 1445 | P33: 1021
C34: OMO | G34: ESPN 4 | I34: MM ABC 25+ CC 02-09 | J34: CAMPOS DOS GOYTACAZES | L34: DIVERSOS | N34: 1410 | O34: 1500 | P34: 1022
C35: RECEPEDIA | G35: ESPN Extra | I35: MM ABC 25+ CPAY TV | J35: CANAA DOS CARAJAS | L35: DOOH | N35: 1415 | O35: 1505 | P35: 1023
C36: REXONA | G36: Flix Media | I36: MM ABC 25-49 | J36: CAPANEMA | L36: ELEVADOR | N36: 1420 | O36: 1515 | P36: 1024
C37: SEDA | G37: Food Network | I37: MM ABCDE 18+ | J37: CARUARU | L37: EMPENA / PAREDE PREDIAL | N37: 1430 | O37: 1520 | P37: 1025
C38: SUAVE | G38: Globo | I38: MM ABCDE 25+ | J38: CASCAVEL | L38: ESTÁDIO | N38: 1435 | O38: 1525 | P38: 1026
C39: SURF | G39: Globo News | I39: MM ABCDE 25-49 | J39: CASTANHAL | L39: EVENTO | N39: 1440 | O39: 1530 | P39: 1027
C40: TRESEMMÉ | G40: Globoplay Novelas | I40: MM C 18+ | J40: CAXIAS DO SUL | L40: FRONTLIGHT | N40: 1445 | O40: 1540 | P40: 1028
C41: UNILEVER BRAND RANGE | G41: Gloob | I41: MM CDE 18+ | J41: CE-ESTADO | L41: INFLUENCER | N41: 1500 | O41: 1545 | P41: 1029
...

Sheet Regras e Combinações Offline
A1: Media Inventory | B1: Voltar Menu
A3: Media Type Description L2 | B3: Media Type Description L3
A4: Cinema | B4: Cinema Foyer Ads
A5: Cinema | B5: Cinema On-Screen Ads
A6: Cinema | B6: Cinema Product Placement
A7: Cinema | B7: Cinema Unidentified (Inactive)
A8: Connected TV | B8: Advertising Video On Demand (AVOD)
A9: Connected TV | B9: Broadcaster Video On Demand (BVOD)
A10: Connected TV | B10: Cable Providers (Inactive)
A11: Connected TV | B11: Connected TV (Inactive)
A12: Connected TV | B12: Full Episode Players (Inactive)
A13: Connected TV | B13: Multiple
... A28: Digital Gaming | B28: Multiple
A29: Digital Video
A30: Digital Video | B30: Cost per Click (Inactive)
A31: Digital Video | B31: Digital place based networks (Inactive)
A32: Digital Video | B32: In Stream Video
A33: Digital Video | B33: Mobile Unidentified (Inactive)
A34: Digital Video | B34: Multiple
A35: Digital Video | B35: Native Video
A36: Digital Video | B36: Other Digital Video (Inactive)
A37: Digital Video | B37: Premium Video (Inactive)
A38: Non Media Channel | B38: Cause Related Mark Activities
A39: Non Media Channel | B39: Event Sponsorships
A40: Non Media Channel | B40: Multiple
A41: Non Media Channel | B41: Not Answered (Inactive)
... A105: TV | B105: TV Spot Airtime

Sheet Guia Nomenclatura de Colunas
A1: Guia Nomenclentura | C1: Voltar Menu
A3: Nomenclatura | B3: Descrição
A4: bd | B4: Colunas que começam com "bd" são as colunas que vêm direto da API
A5: ft | B5: Colunas que começam com "ft" são campos de preenchimento locais
A6: mt | B6: Colunas que começam com "mt" são as campos que refere-se a valores númericos
A7: gl | B7: Colunas que começam com "gl" são campos obrigatorios que são da taxonomia global
A8: tx | B8: Colunas que começam com "tx" são as campos de identificação da taxonomia original

Sheet Versão
A1: Versão
A2: 1.1
